Workbook

Sheet 📖 README — HOW TO USE
A1: 📖 FLEET MANAGEMENT WORKBOOK — USER GUIDE & INSTRUCTIONS
A2: Read this guide before using the workbook for the first time. Share with anyone who will be updating data monthly.
A4: 📊 WHAT THIS WORKBOOK DOES
A5: This workbook automates the monthly fleet performance report for the [COMPANY] field fleet. You paste three raw data exports each month — and the workbook handles the rest: it calculates KPIs, flags speed violations, flags late-night driving, and maintains a running discipline record across all vehicles and drivers.
A7: WORKBOOK TABS AT A GLANCE
A8: TAB NAME | D8: PURPOSE | I8: YOUR MONTHLY ACTION
A9: 📖 README | D9: This guide | I9: Read once. Share with new users.
A10: 📋 FLEET REGISTER | D10: Master list of all vehicles & assigned drivers | I10: Update ONLY when there is a new vehicle, driver change, or transfer. NOT monthly.
A11: 📥 RAW ODOMETER | D11: Monthly GPS odometer export — distance per vehicle | I11: ✅ PASTE new data here every month (start at row 4, column B onward).
A12: 📥 RAW FUEL DATA | D12: Monthly fuel consumption & PJP analysis export | I12: ✅ PASTE new data here every month (start at row 4).
A13: 📥 RAW TRIPS | D13: Trip-level GPS data — every journey logged by tracker | I13: ✅ PASTE new data here every month (start at row 4).
A14: ⚡ MONTHLY ANALYSIS | D14: Auto-calculated metrics for every vehicle | I14: 🚫 DO NOT EDIT. Updates automatically when you paste raw data.
A15: 🚨 SPEED FLAGS | D15: Every trip exceeding 90 km/h — full audit trail | I15: ✏️ Fill in Permission & Discipline Action columns only.
A16: 🌙 LATE HOURS FLAGS | D16: Vehicles driven past 10pm or past midnight | I16: ✏️ Fill in Permission & Discipline Action columns only.
A17: 📝 DISCIPLINE TRACKER | D17: Cumulative record of all warnings and actions — never cleared | I17: ✏️ Add new rows each month. Never delete old entries.
A18: 📊 KPI DASHBOARD | D18: Summary KPIs and regional breakdown — auto-calculated | I18: 🚫 DO NOT EDIT. Read-only summary view.
A20: 📅 MONTHLY UPDATE — STEP BY STEP
B21: ACTION | H21: NOTES / WHERE TO LOOK
A22: 1 | B22: GET THE ODOMETER REPORT from the GPS tracking system (same format as the monthly export) | H22: File is usually named: odometer_report_YYYY_MM_DD.xls
A23: 2 | B23: OPEN the RAW ODOMETER tab in this workbook | H23: Tab is blue. Look for the yellow instruction row at the top.
A24: 3 | B24: CLEAR old data in RAW ODOMETER — select rows 4 downward, columns B to M only. Delete. | H24: ⚠ NEVER delete or overwrite column A — it contains auto-formulas that extract the Reg No key.
A25: 4 | B25: PASTE the new odometer export starting at cell B4 — paste values only (Ctrl+Shift+V) | H25: Column A will auto-populate the Reg No from the Device name. Check it looks correct.
A26: 5 | B26: OPEN the RAW FUEL DATA tab. Clear rows 4 downward. Paste the new fuel analysis export from cell A4. | H26: This tab has no protected columns — paste the full export as-is.
A27: 6 | B27: OPEN the RAW TRIPS tab. Clear rows 4 downward (columns A–G only). Paste trip-level GPS export from A4. | H27: ⚠ Column H (Past Midnight) and Column I (Date) are auto-calculated — do not overwrite them.
A28: 7 | B28: CHECK the MONTHLY ANALYSIS tab — all metrics should now be populated for every vehicle. | H28: Green rows = fully compliant. Red rows = speed violation. Amber rows = late-night driving.
A29: 8 | B29: REVIEW the SPEED FLAGS tab. For each flagged vehicle: select Permission? and fill Discipline Action. | H29: Rows with Permission Granted turn gray. Rows with no action taken glow red.
A30: 9 | B30: REVIEW the LATE HOURS FLAGS tab. Red rows = past midnight. Amber rows = past 10pm only. | H30: Fill in Permission and Discipline Action for each case.
A31: 10 | B31: ADD new entries to the DISCIPLINE TRACKER for every action issued this month. | H31: Add a new row for each verbal warning, official warning, show cause, or hearing. Never delete old rows.
A32: 11 | B32: VIEW the KPI DASHBOARD for the final summary to share with management. | H32: The dashboard updates automatically — no editing needed.
A34: ⚠ PASTING RAW DATA — RULES & WARNINGS
A35: ⛔ ALWAYS paste as VALUES ONLY (not formulas). In Excel: Ctrl+Shift+V → Values. In Google Sheets: Ctrl+Shift+V.
A37: 📥 RAW ODOMETER — Start pasting at cell B4 | Paste columns: B to M | Protected (do not overwrite): A
A38: • Column A auto-extracts Reg No from the Device name (e.g. "KAA 754A SouthRift" → "KAA 754A")
A39: • If column A shows blank or wrong value, check that the Device name in column B starts with the plate number
A40: • The GPS system export may include a blank row 1 and a header row 2 — start your paste at row 4, skipping those
A42: 📥 RAW FUEL DATA — Start pasting at cell A4 | Paste columns: A to Q | Protected (do not overwrite): None
A43: • Paste the entire "PJP Evaluation and Fuel Analysis" sheet export here
A44: • All columns are paste-safe — no protected formulas in this tab
A45: • If a vehicle has zero KM (tracker offline), the KM/L column will show "No Data" — this is expected
A47: 📥 RAW TRIPS — Start pasting at cell A4 | Paste columns: A to G | Protected (do not overwrite): H and I
...

Sheet FLEET REGISTER
A1: 📋 FLEET REGISTER — MASTER VEHICLE & DRIVER DATABASE
A2: Maintain this tab whenever there is a vehicle transfer, new allocation, or driver change. Do NOT modify this tab monthly.
A3: # | B3: Reg No | C3: New Plate | D3: Driver Name | E3: Designation | F3: Region | G3: Territory | H3: Vehicle Type | I3: Make/Model | J3: Tel. Contact
A4: 1 | B4: KAA 754A | C4: KAA 754A | D4: Driver_01 | E4: Stock Controller | F4: South Rift | G4: Territory_26 | H4: Toyota Probox | I4: Toyota Probox | J4: 07XX-XXX-XXX
A5: 2 | B5: KAA 214B | C5: KAA 214B | D5: Driver_02 | E5: ABM | F5: Territory_25 | G5: Territory_19 | H5: Toyota Probox | I5: Toyota Probox | J5: 07XX-XXX-XXX
A6: 3 | B6: KBB 102Q | C6: KBB 102Q | D6: Driver_03 | E6: Stock Controller | F6: Territory_03 | G6: Territory_03 | H6: Toyota Probox | I6: Toyota Probox | J6: 07XX-XXX-XXX
A7: 4 | B7: KBB 103Q | C7: KBB 103Q | D7: Driver_04 | E7: ABM | F7: Territory_03 | G7: Territory_38 | H7: Toyota Probox | I7: Toyota Probox | J7: 07XX-XXX-XXX
A8: 5 | B8: KBB 104Q | C8: KBB 104Q | D8: Driver_05 | E8: Stock Controller | F8: Mountain | G8: Territory_34 | H8: Toyota Probox | I8: Toyota Probox | J8: 07XX-XXX-XXX
A9: 6 | B9: KBB 105Q | C9: KBB 105Q | D9: Driver_06 | E9: Stock Controller | F9: Nyanza | G9: Territory_14 | H9: Toyota Probox | I9: Toyota Probox | J9: 07XX-XXX-XXX
A10: 7 | B10: KBB 106Q | C10: KBB 106Q | D10: Driver_07 | E10: ABM | F10: Territory_42 | G10: Territory_42 | H10: Toyota Probox | I10: Toyota Probox | J10: 07XX-XXX-XXX
A11: 8 | B11: KBB 107Q | C11: KBB 107Q | D11: Driver_08 | E11: Trainer | F11: Mountain | G11: Territory_35 | H11: Toyota Probox | I11: Toyota Probox | J11: 07XX-XXX-XXX
A12: 9 | B12: KBB 108Q | C12: KBB 108Q | D12: Driver_09 | E12: Trainer | F12: North Rift | G12: Territory_08 | H12: Toyota Probox | I12: Toyota Probox | J12: 07XX-XXX-XXX
A13: 10 | B13: KBB 109Q | C13: KBB 109Q | D13: Driver_10 | E13: Trainer | F13: Territory_25 | G13: Territory_37 | H13: Toyota Probox | I13: Toyota Probox | J13: 07XX-XXX-XXX
A14: 11 | B14: KBB 110Q | C14: KBB 110Q | D14: Driver_11 | E14: Trainer | F14: Territory_25 | G14: Territory_19 | H14: Toyota Probox | I14: Toyota Probox | J14: 07XX-XXX-XXX
A15: 12 | B15: KBB 111Q | C15: KBB 111Q | D15: Driver_12 | E15: ABM | F15: North Rift | G15: Territory_16 | H15: Toyota Probox | I15: Toyota Probox | J15: 07XX-XXX-XXX
... A58: 55 | B58: KAAC 315C | C58: KAAC 315C | D58: Driver_55 | E58: TBE | F58: Territory_42 | G58: Territory_20 | H58: Honda | I58: Honda | J58: 07XX-XXX-XXX

Sheet RAW ODOMETER
A1: 📥 RAW ODOMETER — PASTE MONTHLY GPS EXPORT HERE
A2: Each month: paste the full odometer report starting at row 4. Column A auto-extracts the Reg No key from the Device name. Do not edit column A.
A3: Reg No (KEY) ← auto | B3: Device (Raw) | C3: Group | D3: Model | E3: Owner/Manager | F3: Plate Number | G3: Asset No. | H3: Expiry | I3: VIN | J3: Drivers | K3: Start KM | L3: End KM | M3: Distance (km)
A4: =IF(B4="","",IFERROR(LEFT(B4,FIND(" ",B4,FIND(" ",B4)+1)-1),TRIM(B4))) | B4: KAA 754A SouthRift | C4: nan | D4: FMB130 | E4: [COMPANY] | F4: nan | G4: nan | H4: - | I4: NCP160-0003864 | M4: 2142.26
A5: =IF(B5="","",IFERROR(LEFT(B5,FIND(" ",B5,FIND(" ",B5)+1)-1),TRIM(B5))) | B5: KAA 214B Nairobi | C5: [COMPANY] | D5: NSP160-0011848 | E5: [COMPANY] | F5: nan | G5: nan | H5: - | I5: nan | M5: 3381.29
A6: =IF(B6="","",IFERROR(LEFT(B6,FIND(" ",B6,FIND(" ",B6)+1)-1),TRIM(B6))) | B6: KBB 102Q Coast | C6: [COMPANY] | D6: FMB130 | E6: Driver_56 | F6: nan | G6: nan | H6: - | I6: NSP160-0010579 | M6: 1620.01
A7: =IF(B7="","",IFERROR(LEFT(B7,FIND(" ",B7,FIND(" ",B7)+1)-1),TRIM(B7))) | B7: KBB 103Q Coast | C7: [COMPANY] | D7: TOYOTA PROBOX | E7: nan | F7: nan | G7: nan | H7: - | I7: NCP160-0029107 | M7: 2682
A8: =IF(B8="","",IFERROR(LEFT(B8,FIND(" ",B8,FIND(" ",B8)+1)-1),TRIM(B8))) | B8: KBB 104Q Mountain | C8: [COMPANY] | D8: FMB130 | E8: Driver_57 | F8: nan | G8: nan | H8: - | I8: NCP160-0025456 | M8: 2088
A9: =IF(B9="","",IFERROR(LEFT(B9,FIND(" ",B9,FIND(" ",B9)+1)-1),TRIM(B9))) | B9: KBB 105Q Nyanza | C9: [COMPANY] | D9: FMB130 | E9: Driver_58 | F9: nan | G9: nan | H9: - | I9: NSP160-0027728 | M9: 3189.91
A10: =IF(B10="","",IFERROR(LEFT(B10,FIND(" ",B10,FIND(" ",B10)+1)-1),TRIM(B10))) | B10: KBB 106Q Western | C10: nan | D10: FMB130 | E10: Driver_59 | F10: nan | G10: nan | H10: - | I10: NSP160-0013077 | M10: 2600.82
A11: =IF(B11="","",IFERROR(LEFT(B11,FIND(" ",B11,FIND(" ",B11)+1)-1),TRIM(B11))) | B11: KBB 107Q Mountain | C11: [COMPANY] | D11: FMB130 | E11: Driver_59 | F11: KBB 107Q Mountain | G11: KBB 107Q Mountain | H11: - | I11: NSP160-0010447 | M11: 2870.69
A12: =IF(B12="","",IFERROR(LEFT(B12,FIND(" ",B12,FIND(" ",B12)+1)-1),TRIM(B12))) | B12: KBB 108Q NCBA LEASING Nairobi | C12: [COMPANY] | D12: FMB130 | E12: Driver_61 | F12: KBB 108Q Nairobi | G12: KBB 108Q Nairobi | H12: - | I12: NCP160-0025333 | M12: 1853.09
A13: =IF(B13="","",IFERROR(LEFT(B13,FIND(" ",B13,FIND(" ",B13)+1)-1),TRIM(B13))) | B13: KBB 109Q [COMPANY] Nairobi | C13: [COMPANY] | D13: FMB130 | E13: [COMPANY] | F13: KBB 109Q Nairobi | G13: KBB 109Q Nairobi | H13: - | I13: NSP160-0030258 | M13: 2945.51
A14: =IF(B14="","",IFERROR(LEFT(B14,FIND(" ",B14,FIND(" ",B14)+1)-1),TRIM(B14))) | B14: KBB 110Q [COMPANY] Nairobi | C14: [COMPANY] | D14: FMB130 | E14: Driver_67 | F14: nan | G14: nan | H14: - | I14: NSP160-0001732 | M14: 2815.87
A15: =IF(B15="","",IFERROR(LEFT(B15,FIND(" ",B15,FIND(" ",B15)+1)-1),TRIM(B15))) | B15: KDL 137Q Nairobi | C15: [COMPANY] | D15: FMB130 | E15: [COMPANY] | F15: nan | G15: nan | H15: - | I15: NSP160-0031878
A16: =IF(B16="","",IFERROR(LEFT(B16,FIND(" ",B16,FIND(" ",B16)+1)-1),TRIM(B16))) | B16: KBB 111Q North Rift | C16: [COMPANY] | D16: FMB130 | E16: [COMPANY] | F16: nan | G16: nan | H16: - | I16: NCP160-0031857 | M16: 3999.89
A17: =IF(B17="","",IFERROR(LEFT(B17,FIND(" ",B17,FIND(" ",B17)+1)-1),TRIM(B17))) | B17: KBB 112Q Nyanza | C17: [COMPANY] | D17: FMB130 | E17: Nancy Maina | F17: nan | G17: nan | H17: - | I17: NSP160-0028865 | M17: 2941.03
A18: =IF(B18="","",IFERROR(LEFT(B18,FIND(" ",B18,FIND(" ",B18)+1)-1),TRIM(B18))) | B18: KBB 113Q Nyanza | C18: [COMPANY] | D18: nan | E18: nan | F18: nan | G18: nan | H18: - | I18: nan | M18: 2137.26
A19: =IF(B19="","",IFERROR(LEFT(B19,FIND(" ",B19,FIND(" ",B19)+1)-1),TRIM(B19))) | B19: KBB 114Q Nyanza | C19: [COMPANY] | D19: FMB130 | E19: Driver_58 | F19: nan | G19: nan | H19: - | I19: NSP160-0010265 | M19: 1993.96
A20: =IF(B20="","",IFERROR(LEFT(B20,FIND(" ",B20,FIND(" ",B20)+1)-1),TRIM(B20))) | B20: KBB 115Q South Rift | C20: [COMPANY] | D20: FMB130 | E20: Driver_60 | F20: KBB 115Q South Rift | G20: nan | H20: - | I20: NCP160-0011659 | M20: 1927.11
A21: =IF(B21="","",IFERROR(LEFT(B21,FIND(" ",B21,FIND(" ",B21)+1)-1),TRIM(B21))) | B21: KBB 116Q NCBA LEASING S.RIFT | C21: [COMPANY] | D21: FMB130 | E21: KBB 116Q NCBA LEASING S.RIFT | F21: KBB 116Q NCBA LEASING S.RIFT | G21: KBB 116Q NCBA LEASING S.RIFT | H21: - | I21: NSP160-0023336 | M21: 2545.14
A22: =IF(B22="","",IFERROR(LEFT(B22,FIND(" ",B22,FIND(" ",B22)+1)-1),TRIM(B22))) | B22: KBB 117Q Western | C22: [COMPANY] | D22: FMB130 | E22: Driver_57 | F22: nan | G22: nan | H22: - | I22: NSP160-0035026 | M22: 3236.94
A23: =IF(B23="","",IFERROR(LEFT(B23,FIND(" ",B23,FIND(" ",B23)+1)-1),TRIM(B23))) | B23: KBB 118QD LIGHT Coast | C23: [COMPANY] | D23: FMB130 | E23: [COMPANY] | F23: KBB 118QD LIGHT Coast | G23: KBB 118QD LIGHT Coast | H23: - | I23: NCP160-0030430 | M23: 2500.24
A24: =IF(B24="","",IFERROR(LEFT(B24,FIND(" ",B24,FIND(" ",B24)+1)-1),TRIM(B24))) | B24: KBB 119Q South Rift | C24: [COMPANY] | D24: FMB130 | E24: Driver_56 | F24: nan | G24: nan | H24: - | I24: NCP160-0027808 | M24: 3714.06
A25: =IF(B25="","",IFERROR(LEFT(B25,FIND(" ",B25,FIND(" ",B25)+1)-1),TRIM(B25))) | B25: KBB 120Q Nairobi | C25: [COMPANY] | D25: FMB130 | E25: Driver_58 | F25: nan | G25: nan | H25: - | I25: NSP160-0010752 | M25: 2068.13
A26: =IF(B26="","",IFERROR(LEFT(B26,FIND(" ",B26,FIND(" ",B26)+1)-1),TRIM(B26))) | B26: KBB 121Q North Rift | C26: [COMPANY] | D26: FMB130 | E26: Driver_67 | F26: nan | G26: nan | H26: - | I26: NSP160-0011572 | M26: 1997.26
A27: =IF(B27="","",IFERROR(LEFT(B27,FIND(" ",B27,FIND(" ",B27)+1)-1),TRIM(B27))) | B27: KBB 122Q western | C27: [COMPANY] | D27: FMB130 | E27: [COMPANY] | F27: nan | G27: nan | H27: - | I27: NSP160-0031975 | M27: 4157.45
A28: =IF(B28="","",IFERROR(LEFT(B28,FIND(" ",B28,FIND(" ",B28)+1)-1),TRIM(B28))) | B28: KBB 123Q North Rift | C28: [COMPANY] | D28: FMB130 | E28: [COMPANY] | F28: KBB 123Q North Rift | G28: KBB 123Q North Rift | H28: - | I28: NSP160-0029227 | M28: 1417.55
A29: =IF(B29="","",IFERROR(LEFT(B29,FIND(" ",B29,FIND(" ",B29)+1)-1),TRIM(B29))) | B29: KDL 171Q western | C29: [COMPANY] | D29: FMB130 | E29: Driver_68 | F29: nan | G29: nan | H29: - | I29: NSP160-0010097
A30: =IF(B30="","",IFERROR(LEFT(B30,FIND(" ",B30,FIND(" ",B30)+1)-1),TRIM(B30))) | B30: KBB 124Q Mountain | C30: [COMPANY] | D30: FMB130 | E30: Driver_69 | F30: nan | G30: nan | H30: - | I30: NCP160-0009720 | M30: 2323.1
A31: =IF(B31="","",IFERROR(LEFT(B31,FIND(" ",B31,FIND(" ",B31)+1)-1),TRIM(B31))) | B31: KBB 125Q Mountain | C31: [COMPANY] | D31: FMB130 | E31: Driver_70 | F31: nan | G31: nan | H31: - | I31: NCP160-0001986 | M31: 2826.76
A32: =IF(B32="","",IFERROR(LEFT(B32,FIND(" ",B32,FIND(" ",B32)+1)-1),TRIM(B32))) | B32: KBB 126Q Mountain | C32: [COMPANY] | D32: FMB130 | E32: Driver_58 | F32: nan | G32: nan | H32: - | I32: NSP160-0028718 | M32: 2038.07
A33: =IF(B33="","",IFERROR(LEFT(B33,FIND(" ",B33,FIND(" ",B33)+1)-1),TRIM(B33))) | B33: KDL 183Q western | C33: [COMPANY] | D33: FMB130 | E33: Driver_67 | F33: nan | G33: nan | H33: - | I33: NSP160-0010483
A34: =IF(B34="","",IFERROR(LEFT(B34,FIND(" ",B34,FIND(" ",B34)+1)-1),TRIM(B34))) | B34: KBB 127Q Coast | C34: [COMPANY] | D34: FMB130 | E34: Driver_59 | F34: nan | G34: nan | H34: - | I34: NSP160-0010778 | M34: 3683.76
A35: =IF(B35="","",IFERROR(LEFT(B35,FIND(" ",B35,FIND(" ",B35)+1)-1),TRIM(B35))) | B35: KBB 128Q North Rift | C35: [COMPANY] | D35: FMB130 | E35: Driver_62 | F35: nan | G35: nan | H35: - | I35: NCP160-0025978 | M35: 5481.57
A36: =IF(B36="","",IFERROR(LEFT(B36,FIND(" ",B36,FIND(" ",B36)+1)-1),TRIM(B36))) | B36: KAAB 202Z NCBA LSEN | C36: [COMPANY] | D36: FMB920 | E36: Driver_59 | F36: nan | G36: nan | H36: - | I36: nan | M36: 2244.18
A37: =IF(B37="","",IFERROR(LEFT(B37,FIND(" ",B37,FIND(" ",B37)+1)-1),TRIM(B37))) | B37: KAAB 206Z North Rift | C37: [COMPANY] | D37: FMB920 | E37: nan | F37: nan | G37: nan | H37: - | I37: nan
A38: =IF(B38="","",IFERROR(LEFT(B38,FIND(" ",B38,FIND(" ",B38)+1)-1),TRIM(B38))) | B38: KMGH 277Z North Rift | C38: nan | D38: FMB920 | E38: nan | F38: nan | G38: nan | H38: - | I38: nan
A39: =IF(B39="","",IFERROR(LEFT(B39,FIND(" ",B39,FIND(" ",B39)+1)-1),TRIM(B39))) | B39: KAAB 203Z Nairobi | C39: [COMPANY] | D39: FMB920 | E39: nan | F39: nan | G39: nan | H39: - | I39: nan | M39: 2402.01
A40: =IF(B40="","",IFERROR(LEFT(B40,FIND(" ",B40,FIND(" ",B40)+1)-1),TRIM(B40))) | B40: KMGH 292Z South Rift | C40: [COMPANY] | D40: FMB920 | E40: nan | F40: nan | G40: nan | H40: - | I40: nan
...

Sheet RAW FUEL DATA
A1: 📥 RAW FUEL DATA — PASTE MONTHLY FUEL ANALYSIS REPORT HERE
A2: Each month: paste the PJP Evaluation & Fuel Analysis sheet here starting at row 4. Keep headers exactly as exported.
A3: Vehicle Plate | B3: New Plate | C3: Driver Name | D3: Designation | E3: Territory | F3: Vehicle Type | G3: Region | H3: Tracker KM | I3: PJP Compliance | J3: PJP Non-Compliance Reason | K3: Fuel (Litres) | L3: KM/L | M3: Fuel Compliance | N3: Days Past 10pm | O3: Max Top Speed | P3: Date (Top Speed) | Q3: Comment on Speed
A4: KAAB 201Z | B4: KAAB 201Z | C4: Driver_33 | D4: TBE | E4: Territory_17 | F4: Honda | G4: Territory_03 | H4: 1576.35 | K4: 41.89 | L4: 37.630699 | M4: Not Complied | N4: 5 | O4: 87 | P4: 13-02-2026 18:27:59 | Q4: Complied
A5: KAAB 205Z | B5: KAAB 205Z | C5: Driver_40 | D5: TBE | E5: Territory_29 | F5: Honda | G5: North Rift | H5: 1555.23 | K5: 42.68 | L5: 36.439316 | M5: Not Complied | N5: 0 | O5: 83 | P5: 46144.696 | Q5: Complied
A6: KAAC 309C | B6: KAAC 309C | C6: Driver_47 | D6: TBE | E6: Territory_43 | F6: Honda | G6: Nyanza | H6: 515.43 | K6: 40.85 | L6: 12.617625 | M6: Not Complied | N6: 1 | O6: 118 | P6: 46358.628 | Q6: Action Already Taken
A7: KAAB 203Z | B7: KAAB 203Z | C7: Driver_37 | D7: TBE | E7: Territory_33 | F7: Honda | G7: Territory_25 | H7: 2304.27 | K7: 49.59 | L7: 46.466425 | M7: Complied | N7: 6 | O7: 92 | P7: 46024.39 | Q7: Overtaking Instances
A8: KAAB 206Z | B8: KAAB 206Z | C8: Driver_42 | D8: TBE | E8: Territory_10 | F8: Honda | G8: North Rift | H8: 0 | K8: 0 | M8: No Data | N8: 0 | O8: 0 | Q8: Complied
A9: KAAC 308C | B9: KAAC 308C | C9: Driver_45 | D9: TBE | E9: Territory_23 | F9: Honda | G9: North Rift | H9: 1452.63 | K9: 41.33 | L9: 35.147109 | M9: Not Complied | N9: 3 | O9: 85 | P9: 46297.533 | Q9: Complied
A10: KAAC 305C | B10: KAAC 305C | C10: Driver_41 | D10: TBE | E10: Territory_18 | F10: Honda | G10: North Rift | H10: 2445.53 | K10: 39.98 | L10: 61.168834 | M10: Complied | N10: 10 | O10: 96 | P10: 46328.461 | Q10: Overtaking Instances
A11: KAAB 207Z | B11: KAAB 207Z | C11: Driver_46 | D11: TBE | E11: Territory_28 | F11: Honda | G11: North Rift | H11: 1204.23 | K11: 41.83 | L11: 28.788668 | M11: Not Complied | N11: 11 | O11: 93 | P11: 46205.923 | Q11: Overtaking Instances
A12: KAAC 306C | B12: KAAC 306C | C12: Driver_43 | D12: TBE | E12: Territory_04 | F12: Honda | G12: North Rift | H12: 373.92 | K12: 41.5 | L12: 9.0101205 | M12: Not Complied | N12: 0 | O12: 80 | P12: 20-02-2026 19:34:29 | Q12: Complied
A13: KAAC 315C | B13: KAAC 315C | C13: Driver_55 | D13: TBE | E13: Territory_20 | F13: Honda | G13: Territory_42 | H13: 1635.53 | K13: 40.86 | L13: 40.027655 | M13: Not Complied | N13: 4 | O13: 83 | P13: 46144.696 | Q13: Complied
A14: KAAB 209Z | B14: KAAB 209Z | C14: Driver_53 | D14: TBE | E14: Territory_32 | F14: Honda | G14: South Rift | H14: 1013.94 | K14: 32.29 | L14: 31.401053 | M14: Not Complied | N14: 1 | O14: 73 | P14: 46055.823 | Q14: Complied
A15: KAAC 307C | B15: KAAC 307C | C15: Driver_44 | D15: TBE | E15: Territory_16 | F15: Honda | G15: North Rift | H15: 1712.86 | K15: 41.49 | L15: 41.283683 | M15: Not Complied | N15: 1 | O15: 80 | P15: 20-02-2026 19:34:29 | Q15: Complied
A16: KAAC 312C | B16: KAAC 312C | C16: Driver_50 | D16: TBE | E16: Territory_27 | F16: Honda | G16: South Rift | H16: 419.33 | K16: 27.87 | L16: 15.045928 | M16: Not Complied | N16: 0 | O16: 91 | P16: 46358.331 | Q16: Overtaking Instances
A17: KAAC 314C | B17: KAAC 314C | C17: Driver_54 | D17: TBE | E17: Territory_02 | F17: Honda | G17: Territory_42 | H17: 1192.66 | K17: 41.61 | L17: 28.662821 | M17: Not Complied | N17: 0 | O17: 80 | P17: 20-02-2026 19:34:29 | Q17: Complied
A18: KAAC 311C | B18: KAAC 311C | C18: Driver_49 | D18: TBE | E18: Territory_31 | F18: Honda | G18: South Rift | H18: 605.78 | K18: 40.78 | L18: 14.854831 | M18: Not Complied | N18: 2 | O18: 83 | P18: 46144.696 | Q18: Complied
A19: KAAB 200Z | B19: KAAB 200Z | C19: Driver_30 | D19: TBE | E19: Territory_40 | F19: Honda | G19: Territory_03 | H19: 1261.86 | K19: 41.5 | L19: 30.406265 | M19: Not Complied | N19: 5 | O19: 86 | P19: 46297.395 | Q19: Complied
A20: KAAB 202Z | B20: KAAB 202Z | C20: Driver_34 | D20: TBE | E20: Territory_39 | F20: Honda | G20: Territory_03 | H20: 2172.19 | K20: 41.76 | L20: 52.016044 | M20: Complied | N20: 2 | O20: 94 | P20: 13-02-2026 15:26:29 | Q20: Overtaking Instances
A21: KAAC 300C | B21: KAAC 300C | C21: Driver_31 | D21: TBE | E21: Territory_44 | F21: Honda | G21: Territory_03 | H21: 1561.04 | K21: 42.15 | L21: 37.03535 | M21: Not Complied | N21: 1 | O21: 78 | P21: 13-02-2026 18:49:02 | Q21: Complied
A22: KAAB 204Z | B22: KAAB 204Z | C22: Driver_39 | D22: TBE | E22: Territory_11 | F22: Honda | G22: North Rift | H22: 1041.62 | K22: 49.47 | L22: 21.055589 | M22: Not Complied | N22: 0 | O22: 96 | P22: 46328.461 | Q22: Overtaking Instances
A23: KAAC 301C | B23: KAAC 301C | C23: Driver_32 | D23: TBE | E23: Territory_09 | F23: Honda | G23: Territory_03 | H23: 1883.28 | K23: 42.19 | L23: 44.638066 | M23: Not Complied | N23: 11 | O23: 93 | P23: 46205.923 | Q23: Overtaking Instances
A24: KAAC 304C | B24: KAAC 304C | C24: Driver_38 | D24: TBE | E24: Territory_07 | F24: Honda | G24: Territory_25 | H24: 194.64 | K24: 41.36 | L24: 4.7059961 | M24: Not Complied | N24: 1 | O24: 100 | P24: 46328.74 | Q24: Overtaking Instances
A25: KAAC 303C | B25: KAAC 303C | C25: Driver_36 | D25: TBE | E25: Territory_36 | F25: Honda | G25: Territory_25 | H25: 1658.47 | K25: 40.79 | L25: 40.65874 | M25: Not Complied | N25: 6 | O25: 94 | P25: 13-02-2026 15:26:29 | Q25: Overtaking Instances
A26: KAAB 208Z | B26: KAAB 208Z | C26: Driver_51 | D26: TBE | E26: Territory_21 | F26: Honda | G26: South Rift | H26: 1325.83 | K26: 40.87 | L26: 32.440176 | M26: Not Complied | N26: 6 | O26: 87 | P26: 13-02-2026 18:27:59 | Q26: Complied
A27: KAAC 313C | B27: KAAC 313C | C27: Driver_52 | D27: TBE | E27: Territory_01 | F27: Honda | G27: South Rift | H27: 298.75 | K27: 39.36 | L27: 7.5901931 | M27: Not Complied | N27: 1 | O27: 81 | P27: 46358.396 | Q27: Complied
A28: KBB 111Q | B28: KBB 111Q | C28: Driver_12 | D28: ABM | E28: Territory_16 | F28: Toyota Probox | G28: North Rift | H28: 3982.49 | K28: 272.64 | L28: 14.607138 | M28: Complied | N28: 5 | O28: 101 | P28: 46083.63 | Q28: Not Complied
A29: KBB 127Q | B29: KBB 127Q | C29: Driver_28 | D29: ABM | E29: Territory_38 | F29: Toyota Probox | G29: Territory_03 | H29: 3462.78 | K29: 252.54 | L29: 13.711808 | M29: Complied | N29: 2 | O29: 103 | P29: 46144.443 | Q29: Not Complied
A30: KBB 110Q | B30: KBB 110Q | C30: Driver_11 | D30: Trainer | E30: Territory_19 | F30: Toyota Probox | G30: Territory_25 | H30: 2656.59 | K30: 229.62 | L30: 11.569506 | M30: Not Complied | N30: 3 | O30: 101 | P30: 46083.63 | Q30: Permission Granted
A31: KBB 112Q | B31: KBB 112Q | C31: Driver_13 | D31: Trainer | E31: Territory_22 | F31: Toyota Probox | G31: Nyanza | H31: 2908.15 | K31: 273 | L31: 10.652564 | M31: Not Complied | N31: 3 | O31: 87 | P31: 13-02-2026 18:27:59 | Q31: Complied
A32: KBB 128Q | B32: KBB 128Q | C32: Driver_29 | D32: ABM | E32: Territory_05 | F32: Toyota Probox | G32: North Rift | H32: 5326.97 | K32: 220.23 | L32: 24.188212 | M32: Inconsistent | N32: 10 | O32: 97 | P32: 46236.746 | Q32: Overtaking Instances
A33: KBB 108Q | B33: KBB 108Q | C33: Driver_09 | D33: Trainer | E33: Territory_08 | F33: Toyota Probox | G33: North Rift | H33: 2312.23 | K33: 173.12 | L33: 13.356227 | M33: Complied | N33: 0 | O33: 99 | P33: 23-02-2026 10:23:04 | Q33: Overtaking Instances
A34: KBB 105Q | B34: KBB 105Q | C34: Driver_06 | D34: Stock Controller | E34: Territory_14 | F34: Toyota Probox | G34: Nyanza | H34: 3146.72 | K34: 295.23 | L34: 10.658537 | M34: Not Complied | N34: 0 | O34: 92 | P34: 46024.39 | Q34: Overtaking Instances
A35: KBB 103Q | B35: KBB 103Q | C35: Driver_04 | D35: ABM | E35: Territory_38 | F35: Toyota Probox | G35: Territory_03 | H35: 2632.15 | K35: 149.12 | L35: 17.65122 | M35: Inconsistent | N35: 7 | O35: 94 | P35: 13-02-2026 15:26:29 | Q35: Overtaking Instances
A36: KBB 122Q | B36: KBB 122Q | C36: Driver_23 | D36: ABM | E36: Territory_08 | F36: Toyota Probox | G36: Territory_42 | H36: 3906.94 | K36: 269.78 | L36: 14.481948 | M36: Complied | N36: 6 | O36: 99 | P36: 23-02-2026 10:23:04 | Q36: Overtaking Instances
A37: KBB 117Q | B37: KBB 117Q | C37: Driver_18 | D37: ABM | E37: Territory_08 | F37: Toyota Probox | G37: Territory_42 | H37: 2783.54 | K37: 166.27 | L37: 16.741084 | M37: Inconsistent | N37: 7 | O37: 96 | P37: 46328.461 | Q37: Overtaking Instances
A38: KBB 116Q | B38: KBB 116Q | C38: Driver_17 | D38: ABM | E38: Territory_26 | F38: Toyota Probox | G38: South Rift | H38: 2534.73 | K38: 236.3 | L38: 10.726746 | M38: Not Complied | N38: 2 | O38: 94 | P38: 13-02-2026 15:26:29 | Q38: Overtaking Instances
A39: KBB 104Q | B39: KBB 104Q | C39: Driver_05 | D39: Stock Controller | E39: Territory_34 | F39: Toyota Probox | G39: Mountain | H39: 2081.41 | K39: 190.46 | L39: 10.928331 | M39: Not Complied | N39: 1 | O39: 111 | P39: 25-02-2026 06:44:26 | Q39: Action Already Taken
A40: KBB 119Q | B40: KBB 119Q | C40: Driver_20 | D40: ABM | E40: Territory_30 | F40: Toyota Probox | G40: South Rift | H40: 3685.49 | K40: 275.89 | L40: 13.358549 | M40: Complied | N40: 7 | O40: 97 | P40: 46236.746 | Q40: Overtaking Instances
...

Sheet RAW TRIPS
A1: 📥 RAW TRIPS — PASTE TRIP-LEVEL GPS DATA HERE (February Travel Sheet Report)
A2: Each month: paste the full trip-level export. Column H (Past Midnight) is auto-calculated. Do not modify column H. Speed Flags & Late Hours tabs reference this data.
A3: Car Registration | B3: Departure Time | C3: End Time | D3: Route (km) | E3: Avg Speed (km/h) | F3: Top Speed (km/h) | G3: Past 10pm? | H3: Past Midnight? | I3: Date
A4: KAA 754A | B4: 46024.407 | C4: 46024.408 | D4: 0.01 Km | E4: 6 | F4: 6 | G4: No | H4: =IF(A4="","",IF(OR(NOT(ISNUMBER(C4)),C4=""),"No",IF(AND(HOUR(C4)>=0,HOUR(C4)<5),"Yes","No"))) | I4: =IF(OR(B4="",NOT(ISNUMBER(B4))),"",INT(B4))
A5: KAA 754A | B5: 46024.432 | C5: 46024.433 | D5: 0.01 Km | E5: 7 | F5: 8 | G5: No | H5: =IF(A5="","",IF(OR(NOT(ISNUMBER(C5)),C5=""),"No",IF(AND(HOUR(C5)>=0,HOUR(C5)<5),"Yes","No"))) | I5: =IF(OR(B5="",NOT(ISNUMBER(B5))),"",INT(B5))
A6: KAA 754A | B6: 46024.724 | C6: 46024.733 | D6: 2.45 Km | E6: 14 | F6: 35 | G6: No | H6: =IF(A6="","",IF(OR(NOT(ISNUMBER(C6)),C6=""),"No",IF(AND(HOUR(C6)>=0,HOUR(C6)<5),"Yes","No"))) | I6: =IF(OR(B6="",NOT(ISNUMBER(B6))),"",INT(B6))
A7: KAA 754A | B7: 46024.755 | C7: 46024.759 | D7: 0.99 Km | E7: 12 | F7: 26 | G7: No | H7: =IF(A7="","",IF(OR(NOT(ISNUMBER(C7)),C7=""),"No",IF(AND(HOUR(C7)>=0,HOUR(C7)<5),"Yes","No"))) | I7: =IF(OR(B7="",NOT(ISNUMBER(B7))),"",INT(B7))
A8: KAA 754A | B8: 46144.463 | C8: 46144.464 | D8: 0.07 Km | E8: 7 | F8: 9 | G8: No | H8: =IF(A8="","",IF(OR(NOT(ISNUMBER(C8)),C8=""),"No",IF(AND(HOUR(C8)>=0,HOUR(C8)<5),"Yes","No"))) | I8: =IF(OR(B8="",NOT(ISNUMBER(B8))),"",INT(B8))
A9: KAA 754A | B9: 46144.633 | C9: 46144.634 | D9: 0.04 Km | E9: 7 | F9: 9 | G9: No | H9: =IF(A9="","",IF(OR(NOT(ISNUMBER(C9)),C9=""),"No",IF(AND(HOUR(C9)>=0,HOUR(C9)<5),"Yes","No"))) | I9: =IF(OR(B9="",NOT(ISNUMBER(B9))),"",INT(B9))
A10: KAA 754A | B10: 46144.665 | C10: 46144.666 | D10: 0.09 Km | E10: 7 | F10: 10 | G10: No | H10: =IF(A10="","",IF(OR(NOT(ISNUMBER(C10)),C10=""),"No",IF(AND(HOUR(C10)>=0,HOUR(C10)<5),"Yes","No"))) | I10: =IF(OR(B10="",NOT(ISNUMBER(B10))),"",INT(B10))
A11: KAA 754A | B11: 46144.671 | C11: 46144.687 | D11: 11.31 Km | E11: 30 | F11: 74 | G11: No | H11: =IF(A11="","",IF(OR(NOT(ISNUMBER(C11)),C11=""),"No",IF(AND(HOUR(C11)>=0,HOUR(C11)<5),"Yes","No"))) | I11: =IF(OR(B11="",NOT(ISNUMBER(B11))),"",INT(B11))
A12: KAA 754A | B12: 46144.687 | C12: 46144.696 | D12: 5.06 Km | E12: 28 | F12: 83 | G12: No | H12: =IF(A12="","",IF(OR(NOT(ISNUMBER(C12)),C12=""),"No",IF(AND(HOUR(C12)>=0,HOUR(C12)<5),"Yes","No"))) | I12: =IF(OR(B12="",NOT(ISNUMBER(B12))),"",INT(B12))
A13: KAA 754A | B13: 46144.697 | C13: 46144.707 | D13: 2.14 Km | E13: 14 | F13: 42 | G13: No | H13: =IF(A13="","",IF(OR(NOT(ISNUMBER(C13)),C13=""),"No",IF(AND(HOUR(C13)>=0,HOUR(C13)<5),"Yes","No"))) | I13: =IF(OR(B13="",NOT(ISNUMBER(B13))),"",INT(B13))
A14: KAA 754A | B14: 46144.725 | C14: 46144.739 | D14: 3.78 Km | E14: 17 | F14: 48 | G14: No | H14: =IF(A14="","",IF(OR(NOT(ISNUMBER(C14)),C14=""),"No",IF(AND(HOUR(C14)>=0,HOUR(C14)<5),"Yes","No"))) | I14: =IF(OR(B14="",NOT(ISNUMBER(B14))),"",INT(B14))
A15: KAA 754A | B15: 46144.742 | C15: 46144.75 | D15: 4.53 Km | E15: 23 | F15: 60 | G15: No | H15: =IF(A15="","",IF(OR(NOT(ISNUMBER(C15)),C15=""),"No",IF(AND(HOUR(C15)>=0,HOUR(C15)<5),"Yes","No"))) | I15: =IF(OR(B15="",NOT(ISNUMBER(B15))),"",INT(B15))
... A71: KAA 754A | B71: 46358.755 | C71: 46358.756 | D71: 0.07 Km | E71: 8 | F71: 11 | G71: No | H71: =IF(A71="","",IF(OR(NOT(ISNUMBER(C71)),C71=""),"No",IF(AND(HOUR(C71)>=0,HOUR(C71)<5),"Yes","No"))) | I71: =IF(OR(B71="",NOT(ISNUMBER(B71))),"",INT(B71))
A72: KAA 754A | B72: 13-02-2026 09:21:00 | C72: 13-02-2026 09:21:58 | D72: 0.05 Km | E72: 7 | F72: 7 | G72: No | H72: =IF(A72="","",IF(OR(NOT(ISNUMBER(C72)),C72=""),"No",IF(AND(HOUR(C72)>=0,HOUR(C72)<5),"Yes","No"))) | I72: =IF(OR(B72="",NOT(ISNUMBER(B72))),"",INT(B72))
A73: KAA 754A | B73: 13-02-2026 09:38:33 | C73: 13-02-2026 09:40:44 | D73: 0.33 Km | E73: 12 | F73: 23 | G73: No | H73: =IF(A73="","",IF(OR(NOT(ISNUMBER(C73)),C73=""),"No",IF(AND(HOUR(C73)>=0,HOUR(C73)<5),"Yes","No"))) | I73: =IF(OR(B73="",NOT(ISNUMBER(B73))),"",INT(B73))
A74: KAA 754A | B74: 13-02-2026 09:44:54 | C74: 13-02-2026 09:47:04 | D74: 0.39 Km | E74: 12 | F74: 28 | G74: No | H74: =IF(A74="","",IF(OR(NOT(ISNUMBER(C74)),C74=""),"No",IF(AND(HOUR(C74)>=0,HOUR(C74)<5),"Yes","No"))) | I74: =IF(OR(B74="",NOT(ISNUMBER(B74))),"",INT(B74))
A75: KAA 754A | B75: 13-02-2026 10:20:37 | C75: 13-02-2026 10:22:20 | D75: 0.4 Km | E75: 15 | F75: 30 | G75: No | H75: =IF(A75="","",IF(OR(NOT(ISNUMBER(C75)),C75=""),"No",IF(AND(HOUR(C75)>=0,HOUR(C75)<5),"Yes","No"))) | I75: =IF(OR(B75="",NOT(ISNUMBER(B75))),"",INT(B75))
A76: KAA 754A | B76: 13-02-2026 12:52:48 | C76: 13-02-2026 12:55:17 | D76: 0.32 Km | E76: 15 | F76: 23 | G76: No | H76: =IF(A76="","",IF(OR(NOT(ISNUMBER(C76)),C76=""),"No",IF(AND(HOUR(C76)>=0,HOUR(C76)<5),"Yes","No"))) | I76: =IF(OR(B76="",NOT(ISNUMBER(B76))),"",INT(B76))
A77: KAA 754A | B77: 13-02-2026 12:59:21 | C77: 13-02-2026 13:30:38 | D77: 35.59 Km | E77: 68 | F77: 90 | G77: No | H77: =IF(A77="","",IF(OR(NOT(ISNUMBER(C77)),C77=""),"No",IF(AND(HOUR(C77)>=0,HOUR(C77)<5),"Yes","No"))) | I77: =IF(OR(B77="",NOT(ISNUMBER(B77))),"",INT(B77))
A78: KAA 754A | B78: 13-02-2026 14:14:18 | C78: 13-02-2026 14:16:07 | D78: 0.55 Km | E78: 18 | F78: 41 | G78: No | H78: =IF(A78="","",IF(OR(NOT(ISNUMBER(C78)),C78=""),"No",IF(AND(HOUR(C78)>=0,HOUR(C78)<5),"Yes","No"))) | I78: =IF(OR(B78="",NOT(ISNUMBER(B78))),"",INT(B78))
A79: KAA 754A | B79: 13-02-2026 14:20:55 | C79: 13-02-2026 15:26:29 | D79: 74.28 Km | E79: 68 | F79: 94 | G79: No | H79: =IF(A79="","",IF(OR(NOT(ISNUMBER(C79)),C79=""),"No",IF(AND(HOUR(C79)>=0,HOUR(C79)<5),"Yes","No"))) | I79: =IF(OR(B79="",NOT(ISNUMBER(B79))),"",INT(B79))
A80: KAA 754A | B80: 13-02-2026 15:29:04 | C80: 13-02-2026 15:30:26 | D80: 0.14 Km | E80: 8 | F80: 12 | G80: No | H80: =IF(A80="","",IF(OR(NOT(ISNUMBER(C80)),C80=""),"No",IF(AND(HOUR(C80)>=0,HOUR(C80)<5),"Yes","No"))) | I80: =IF(OR(B80="",NOT(ISNUMBER(B80))),"",INT(B80))
A81: KAA 754A | B81: 13-02-2026 15:40:46 | C81: 13-02-2026 15:45:50 | D81: 1.94 Km | E81: 22 | F81: 54 | G81: No | H81: =IF(A81="","",IF(OR(NOT(ISNUMBER(C81)),C81=""),"No",IF(AND(HOUR(C81)>=0,HOUR(C81)<5),"Yes","No"))) | I81: =IF(OR(B81="",NOT(ISNUMBER(B81))),"",INT(B81))
A82: KAA 754A | B82: 13-02-2026 16:06:10 | C82: 13-02-2026 16:12:28 | D82: 1.9 Km | E82: 19 | F82: 48 | G82: No | H82: =IF(A82="","",IF(OR(NOT(ISNUMBER(C82)),C82=""),"No",IF(AND(HOUR(C82)>=0,HOUR(C82)<5),"Yes","No"))) | I82: =IF(OR(B82="",NOT(ISNUMBER(B82))),"",INT(B82))
A83: KAA 754A | B83: 13-02-2026 16:16:46 | C83: 13-02-2026 16:31:32 | D83: 12.07 Km | E83: 57 | F83: 76 | G83: No | H83: =IF(A83="","",IF(OR(NOT(ISNUMBER(C83)),C83=""),"No",IF(AND(HOUR(C83)>=0,HOUR(C83)<5),"Yes","No"))) | I83: =IF(OR(B83="",NOT(ISNUMBER(B83))),"",INT(B83))
... A160: KAA 754A | B160: 25-02-2026 17:40:05 | C160: 25-02-2026 18:22:42 | D160: 9.2 Km | E160: 19 | F160: 57 | G160: No | H160: =IF(A160="","",IF(OR(NOT(ISNUMBER(C160)),C160=""),"No",IF(AND(HOUR(C160)>=0,HOUR(C160)<5),"Yes","No"))) | I160: =IF(OR(B160="",NOT(ISNUMBER(B160))),"",INT(B160))
A161: KAA 214B | B161: 46024.334 | C161: 46024.363 | D161: 29.91 Km | E161: 42 | F161: 78 | G161: No | H161: =IF(A161="","",IF(OR(NOT(ISNUMBER(C161)),C161=""),"No",IF(AND(HOUR(C161)>=0,HOUR(C161)<5),"Yes","No"))) | I161: =IF(OR(B161="",NOT(ISNUMBER(B161))),"",INT(B161))
A162: KAA 214B | B162: 46024.591 | C162: 46024.611 | D162: 11.15 Km | E162: 26 | F162: 64 | G162: No | H162: =IF(A162="","",IF(OR(NOT(ISNUMBER(C162)),C162=""),"No",IF(AND(HOUR(C162)>=0,HOUR(C162)<5),"Yes","No"))) | I162: =IF(OR(B162="",NOT(ISNUMBER(B162))),"",INT(B162))
A163: KAA 214B | B163: 46024.62 | C163: 46024.642 | D163: 22.28 Km | E163: 42 | F163: 86 | G163: No | H163: =IF(A163="","",IF(OR(NOT(ISNUMBER(C163)),C163=""),"No",IF(AND(HOUR(C163)>=0,HOUR(C163)<5),"Yes","No"))) | I163: =IF(OR(B163="",NOT(ISNUMBER(B163))),"",INT(B163))
A164: KAA 214B | B164: 46024.788 | C164: 46024.802 | D164: 5.67 Km | E164: 16 | F164: 61 | G164: No | H164: =IF(A164="","",IF(OR(NOT(ISNUMBER(C164)),C164=""),"No",IF(AND(HOUR(C164)>=0,HOUR(C164)<5),"Yes","No"))) | I164: =IF(OR(B164="",NOT(ISNUMBER(B164))),"",INT(B164))
A165: KAA 214B | B165: 46055.432 | C165: 46055.462 | D165: 26.53 Km | E165: 39 | F165: 75 | G165: No | H165: =IF(A165="","",IF(OR(NOT(ISNUMBER(C165)),C165=""),"No",IF(AND(HOUR(C165)>=0,HOUR(C165)<5),"Yes","No"))) | I165: =IF(OR(B165="",NOT(ISNUMBER(B165))),"",INT(B165))
A166: KAA 214B | B166: 46055.481 | C166: 46055.483 | D166: 0.69 Km | E166: 11 | F166: 33 | G166: No | H166: =IF(A166="","",IF(OR(NOT(ISNUMBER(C166)),C166=""),"No",IF(AND(HOUR(C166)>=0,HOUR(C166)<5),"Yes","No"))) | I166: =IF(OR(B166="",NOT(ISNUMBER(B166))),"",INT(B166))
A167: KAA 214B | B167: 46055.763 | C167: 46055.792 | D167: 23.98 Km | E167: 35 | F167: 84 | G167: No | H167: =IF(A167="","",IF(OR(NOT(ISNUMBER(C167)),C167=""),"No",IF(AND(HOUR(C167)>=0,HOUR(C167)<5),"Yes","No"))) | I167: =IF(OR(B167="",NOT(ISNUMBER(B167))),"",INT(B167))
A168: KAA 214B | B168: 46083.429 | C168: 46083.43 | D168: 0.02 Km | E168: 8 | F168: 8 | G168: No | H168: =IF(A168="","",IF(OR(NOT(ISNUMBER(C168)),C168=""),"No",IF(AND(HOUR(C168)>=0,HOUR(C168)<5),"Yes","No"))) | I168: =IF(OR(B168="",NOT(ISNUMBER(B168))),"",INT(B168))
A169: KAA 214B | B169: 46083.437 | C169: 46083.482 | D169: 44.74 Km | E169: 43 | F169: 81 | G169: No | H169: =IF(A169="","",IF(OR(NOT(ISNUMBER(C169)),C169=""),"No",IF(AND(HOUR(C169)>=0,HOUR(C169)<5),"Yes","No"))) | I169: =IF(OR(B169="",NOT(ISNUMBER(B169))),"",INT(B169))
A170: KAA 214B | B170: 46083.709 | C170: 46083.746 | D170: 37.4 Km | E170: 43 | F170: 79 | G170: No | H170: =IF(A170="","",IF(OR(NOT(ISNUMBER(C170)),C170=""),"No",IF(AND(HOUR(C170)>=0,HOUR(C170)<5),"Yes","No"))) | I170: =IF(OR(B170="",NOT(ISNUMBER(B170))),"",INT(B170))
A171: KAA 214B | B171: 46083.748 | C171: 46083.75 | D171: 0.14 Km | E171: 6 | F171: 7 | G171: No | H171: =IF(A171="","",IF(OR(NOT(ISNUMBER(C171)),C171=""),"No",IF(AND(HOUR(C171)>=0,HOUR(C171)<5),"Yes","No"))) | I171: =IF(OR(B171="",NOT(ISNUMBER(B171))),"",INT(B171))
...

Sheet MONTHLY ANALYSIS
A1: ⚡ MONTHLY ANALYSIS — AUTO-POPULATED VIA XLOOKUP
A2: This tab auto-fills from the RAW tabs. Paste new data in Tabs 2–4 and all metrics update automatically. Do NOT manually edit columns B–R.
A3: Reg No | B3: Driver Name | C3: Designation | D3: Region | E3: Territory | F3: Vehicle Type | G3: Tracker KM | H3: Fuel (L) | I3: KM/L | J3: KM/L Threshold | K3: Fuel Compliance | L3: Days Past 10pm | M3: Days Past Midnight | N3: Max Speed (km/h) | O3: Speed Compliance | P3: ⚑ Speed Flag | Q3: ⚑ Late Hours Flag | R3: ⚑ Fuel Flag
A4: KAA 754A | B4: =IFERROR(xlookup(A4,'FLEET REGISTER'!$B:$B,'FLEET REGISTER'!$D:$D),"—") | C4: =IFERROR(xlookup(A4,'FLEET REGISTER'!$B:$B,'FLEET REGISTER'!$E:$E),"—") | D4: =IFERROR(xlookup(A4,'FLEET REGISTER'!$B:$B,'FLEET REGISTER'!$F:$F),"—") | E4: =IFERROR(xlookup(A4,'FLEET REGISTER'!$B:$B,'FLEET REGISTER'!$G:$G),"—") | F4: =IFERROR(xlookup(A4,'FLEET REGISTER'!$B:$B,'FLEET REGISTER'!$H:$H),"—") | G4: =IFERROR(xlookup(A4,'RAW ODOMETER'!$A:$A,'RAW ODOMETER'!$M:$M,0),0) | H4: =IFERROR(xlookup(A4,'RAW FUEL DATA'!$A:$A,'RAW FUEL DATA'!$K:$K,0),0) | I4: =IFERROR(xlookup(A4,'RAW FUEL DATA'!$A:$A,'RAW FUEL DATA'!$L:$L,0),0) | J4: =IF(F4="Honda",40.5,12.6) | K4: =IF(I4=0,"No Data",IF(I4>=J4,"✔ Complied","✘ Not Complied")) | L4: =IFERROR(COUNTIFS('RAW TRIPS'!$A:$A,A4,'RAW TRIPS'!$G:$G,"Yes"),0) | M4: =IFERROR(COUNTIFS('RAW TRIPS'!$A:$A,A4,'RAW TRIPS'!$H:$H,"Yes"),0) | N4: =IFERROR(maxifs('RAW TRIPS'!$F:$F,'RAW TRIPS'!$A:$A,A4),0) | O4: =IF(N4=0,"No Data",IF(N4<=90,"✔ Complied","✘ SPEEDING")) | P4: =IF(N4>90,"⚑ SPEED VIOLATION","") | Q4: =IF(M4>0,"⚑ PAST MIDNIGHT",IF(L4>0,"⚑ PAST 10PM","")) | R4: =IF(K4="✘ Not Complied","⚑ FUEL NON-COMPLIANT","")
A5: KAA 214B | B5: =IFERROR(xlookup(A5,'FLEET REGISTER'!$B:$B,'FLEET REGISTER'!$D:$D),"—") | C5: =IFERROR(xlookup(A5,'FLEET REGISTER'!$B:$B,'FLEET REGISTER'!$E:$E),"—") | D5: =IFERROR(xlookup(A5,'FLEET REGISTER'!$B:$B,'FLEET REGISTER'!$F:$F),"—") | E5: =IFERROR(xlookup(A5,'FLEET REGISTER'!$B:$B,'FLEET REGISTER'!$G:$G),"—") | F5: =IFERROR(xlookup(A5,'FLEET REGISTER'!$B:$B,'FLEET REGISTER'!$H:$H),"—") | G5: =IFERROR(xlookup(A5,'RAW ODOMETER'!$A:$A,'RAW ODOMETER'!$M:$M,0),0) | H5: =IFERROR(xlookup(A5,'RAW FUEL DATA'!$A:$A,'RAW FUEL DATA'!$K:$K,0),0) | I5: =IFERROR(xlookup(A5,'RAW FUEL DATA'!$A:$A,'RAW FUEL DATA'!$L:$L,0),0) | J5: =IF(F5="Honda",40.5,12.6) | K5: =IF(I5=0,"No Data",IF(I5>=J5,"✔ Complied","✘ Not Complied")) | L5: =IFERROR(COUNTIFS('RAW TRIPS'!$A:$A,A5,'RAW TRIPS'!$G:$G,"Yes"),0) | M5: =IFERROR(COUNTIFS('RAW TRIPS'!$A:$A,A5,'RAW TRIPS'!$H:$H,"Yes"),0) | N5: =IFERROR(maxifs('RAW TRIPS'!$F:$F,'RAW TRIPS'!$A:$A,A5),0) | O5: =IF(N5=0,"No Data",IF(N5<=90,"✔ Complied","✘ SPEEDING")) | P5: =IF(N5>90,"⚑ SPEED VIOLATION","") | Q5: =IF(M5>0,"⚑ PAST MIDNIGHT",IF(L5>0,"⚑ PAST 10PM","")) | R5: =IF(K5="✘ Not Complied","⚑ FUEL NON-COMPLIANT","")
A6: KBB 102Q | B6: =IFERROR(xlookup(A6,'FLEET REGISTER'!$B:$B,'FLEET REGISTER'!$D:$D),"—") | C6: =IFERROR(xlookup(A6,'FLEET REGISTER'!$B:$B,'FLEET REGISTER'!$E:$E),"—") | D6: =IFERROR(xlookup(A6,'FLEET REGISTER'!$B:$B,'FLEET REGISTER'!$F:$F),"—") | E6: =IFERROR(xlookup(A6,'FLEET REGISTER'!$B:$B,'FLEET REGISTER'!$G:$G),"—") | F6: =IFERROR(xlookup(A6,'FLEET REGISTER'!$B:$B,'FLEET REGISTER'!$H:$H),"—") | G6: =IFERROR(xlookup(A6,'RAW ODOMETER'!$A:$A,'RAW ODOMETER'!$M:$M,0),0) | H6: =IFERROR(xlookup(A6,'RAW FUEL DATA'!$A:$A,'RAW FUEL DATA'!$K:$K,0),0) | I6: =IFERROR(xlookup(A6,'RAW FUEL DATA'!$A:$A,'RAW FUEL DATA'!$L:$L,0),0) | J6: =IF(F6="Honda",40.5,12.6) | K6: =IF(I6=0,"No Data",IF(I6>=J6,"✔ Complied","✘ Not Complied")) | L6: =IFERROR(COUNTIFS('RAW TRIPS'!$A:$A,A6,'RAW TRIPS'!$G:$G,"Yes"),0) | M6: =IFERROR(COUNTIFS('RAW TRIPS'!$A:$A,A6,'RAW TRIPS'!$H:$H,"Yes"),0) | N6: =IFERROR(maxifs('RAW TRIPS'!$F:$F,'RAW TRIPS'!$A:$A,A6),0) | O6: =IF(N6=0,"No Data",IF(N6<=90,"✔ Complied","✘ SPEEDING")) | P6: =IF(N6>90,"⚑ SPEED VIOLATION","") | Q6: =IF(M6>0,"⚑ PAST MIDNIGHT",IF(L6>0,"⚑ PAST 10PM","")) | R6: =IF(K6="✘ Not Complied","⚑ FUEL NON-COMPLIANT","")
A7: KBB 103Q | B7: =IFERROR(xlookup(A7,'FLEET REGISTER'!$B:$B,'FLEET REGISTER'!$D:$D),"—") | C7: =IFERROR(xlookup(A7,'FLEET REGISTER'!$B:$B,'FLEET REGISTER'!$E:$E),"—") | D7: =IFERROR(xlookup(A7,'FLEET REGISTER'!$B:$B,'FLEET REGISTER'!$F:$F),"—") | E7: =IFERROR(xlookup(A7,'FLEET REGISTER'!$B:$B,'FLEET REGISTER'!$G:$G),"—") | F7: =IFERROR(xlookup(A7,'FLEET REGISTER'!$B:$B,'FLEET REGISTER'!$H:$H),"—") | G7: =IFERROR(xlookup(A7,'RAW ODOMETER'!$A:$A,'RAW ODOMETER'!$M:$M,0),0) | H7: =IFERROR(xlookup(A7,'RAW FUEL DATA'!$A:$A,'RAW FUEL DATA'!$K:$K,0),0) | I7: =IFERROR(xlookup(A7,'RAW FUEL DATA'!$A:$A,'RAW FUEL DATA'!$L:$L,0),0) | J7: =IF(F7="Honda",40.5,12.6) | K7: =IF(I7=0,"No Data",IF(I7>=J7,"✔ Complied","✘ Not Complied")) | L7: =IFERROR(COUNTIFS('RAW TRIPS'!$A:$A,A7,'RAW TRIPS'!$G:$G,"Yes"),0) | M7: =IFERROR(COUNTIFS('RAW TRIPS'!$A:$A,A7,'RAW TRIPS'!$H:$H,"Yes"),0) | N7: =IFERROR(maxifs('RAW TRIPS'!$F:$F,'RAW TRIPS'!$A:$A,A7),0) | O7: =IF(N7=0,"No Data",IF(N7<=90,"✔ Complied","✘ SPEEDING")) | P7: =IF(N7>90,"⚑ SPEED VIOLATION","") | Q7: =IF(M7>0,"⚑ PAST MIDNIGHT",IF(L7>0,"⚑ PAST 10PM","")) | R7: =IF(K7="✘ Not Complied","⚑ FUEL NON-COMPLIANT","")
A8: KBB 104Q | B8: =IFERROR(xlookup(A8,'FLEET REGISTER'!$B:$B,'FLEET REGISTER'!$D:$D),"—") | C8: =IFERROR(xlookup(A8,'FLEET REGISTER'!$B:$B,'FLEET REGISTER'!$E:$E),"—") | D8: =IFERROR(xlookup(A8,'FLEET REGISTER'!$B:$B,'FLEET REGISTER'!$F:$F),"—") | E8: =IFERROR(xlookup(A8,'FLEET REGISTER'!$B:$B,'FLEET REGISTER'!$G:$G),"—") | F8: =IFERROR(xlookup(A8,'FLEET REGISTER'!$B:$B,'FLEET REGISTER'!$H:$H),"—") | G8: =IFERROR(xlookup(A8,'RAW ODOMETER'!$A:$A,'RAW ODOMETER'!$M:$M,0),0) | H8: =IFERROR(xlookup(A8,'RAW FUEL DATA'!$A:$A,'RAW FUEL DATA'!$K:$K,0),0) | I8: =IFERROR(xlookup(A8,'RAW FUEL DATA'!$A:$A,'RAW FUEL DATA'!$L:$L,0),0) | J8: =IF(F8="Honda",40.5,12.6) | K8: =IF(I8=0,"No Data",IF(I8>=J8,"✔ Complied","✘ Not Complied")) | L8: =IFERROR(COUNTIFS('RAW TRIPS'!$A:$A,A8,'RAW TRIPS'!$G:$G,"Yes"),0) | M8: =IFERROR(COUNTIFS('RAW TRIPS'!$A:$A,A8,'RAW TRIPS'!$H:$H,"Yes"),0) | N8: =IFERROR(maxifs('RAW TRIPS'!$F:$F,'RAW TRIPS'!$A:$A,A8),0) | O8: =IF(N8=0,"No Data",IF(N8<=90,"✔ Complied","✘ SPEEDING")) | P8: =IF(N8>90,"⚑ SPEED VIOLATION","") | Q8: =IF(M8>0,"⚑ PAST MIDNIGHT",IF(L8>0,"⚑ PAST 10PM","")) | R8: =IF(K8="✘ Not Complied","⚑ FUEL NON-COMPLIANT","")
A9: KBB 105Q | B9: =IFERROR(xlookup(A9,'FLEET REGISTER'!$B:$B,'FLEET REGISTER'!$D:$D),"—") | C9: =IFERROR(xlookup(A9,'FLEET REGISTER'!$B:$B,'FLEET REGISTER'!$E:$E),"—") | D9: =IFERROR(xlookup(A9,'FLEET REGISTER'!$B:$B,'FLEET REGISTER'!$F:$F),"—") | E9: =IFERROR(xlookup(A9,'FLEET REGISTER'!$B:$B,'FLEET REGISTER'!$G:$G),"—") | F9: =IFERROR(xlookup(A9,'FLEET REGISTER'!$B:$B,'FLEET REGISTER'!$H:$H),"—") | G9: =IFERROR(xlookup(A9,'RAW ODOMETER'!$A:$A,'RAW ODOMETER'!$M:$M,0),0) | H9: =IFERROR(xlookup(A9,'RAW FUEL DATA'!$A:$A,'RAW FUEL DATA'!$K:$K,0),0) | I9: =IFERROR(xlookup(A9,'RAW FUEL DATA'!$A:$A,'RAW FUEL DATA'!$L:$L,0),0) | J9: =IF(F9="Honda",40.5,12.6) | K9: =IF(I9=0,"No Data",IF(I9>=J9,"✔ Complied","✘ Not Complied")) | L9: =IFERROR(COUNTIFS('RAW TRIPS'!$A:$A,A9,'RAW TRIPS'!$G:$G,"Yes"),0) | M9: =IFERROR(COUNTIFS('RAW TRIPS'!$A:$A,A9,'RAW TRIPS'!$H:$H,"Yes"),0) | N9: =IFERROR(maxifs('RAW TRIPS'!$F:$F,'RAW TRIPS'!$A:$A,A9),0) | O9: =IF(N9=0,"No Data",IF(N9<=90,"✔ Complied","✘ SPEEDING")) | P9: =IF(N9>90,"⚑ SPEED VIOLATION","") | Q9: =IF(M9>0,"⚑ PAST MIDNIGHT",IF(L9>0,"⚑ PAST 10PM","")) | R9: =IF(K9="✘ Not Complied","⚑ FUEL NON-COMPLIANT","")
A10: KBB 106Q | B10: =IFERROR(xlookup(A10,'FLEET REGISTER'!$B:$B,'FLEET REGISTER'!$D:$D),"—") | C10: =IFERROR(xlookup(A10,'FLEET REGISTER'!$B:$B,'FLEET REGISTER'!$E:$E),"—") | D10: =IFERROR(xlookup(A10,'FLEET REGISTER'!$B:$B,'FLEET REGISTER'!$F:$F),"—") | E10: =IFERROR(xlookup(A10,'FLEET REGISTER'!$B:$B,'FLEET REGISTER'!$G:$G),"—") | F10: =IFERROR(xlookup(A10,'FLEET REGISTER'!$B:$B,'FLEET REGISTER'!$H:$H),"—") | G10: =IFERROR(xlookup(A10,'RAW ODOMETER'!$A:$A,'RAW ODOMETER'!$M:$M,0),0) | H10: =IFERROR(xlookup(A10,'RAW FUEL DATA'!$A:$A,'RAW FUEL DATA'!$K:$K,0),0) | I10: =IFERROR(xlookup(A10,'RAW FUEL DATA'!$A:$A,'RAW FUEL DATA'!$L:$L,0),0) | J10: =IF(F10="Honda",40.5,12.6) | K10: =IF(I10=0,"No Data",IF(I10>=J10,"✔ Complied","✘ Not Complied")) | L10: =IFERROR(COUNTIFS('RAW TRIPS'!$A:$A,A10,'RAW TRIPS'!$G:$G,"Yes"),0) | M10: =IFERROR(COUNTIFS('RAW TRIPS'!$A:$A,A10,'RAW TRIPS'!$H:$H,"Yes"),0) | N10: =IFERROR(maxifs('RAW TRIPS'!$F:$F,'RAW TRIPS'!$A:$A,A10),0) | O10: =IF(N10=0,"No Data",IF(N10<=90,"✔ Complied","✘ SPEEDING")) | P10: =IF(N10>90,"⚑ SPEED VIOLATION","") | Q10: =IF(M10>0,"⚑ PAST MIDNIGHT",IF(L10>0,"⚑ PAST 10PM","")) | R10: =IF(K10="✘ Not Complied","⚑ FUEL NON-COMPLIANT","")
A11: KBB 107Q | B11: =IFERROR(xlookup(A11,'FLEET REGISTER'!$B:$B,'FLEET REGISTER'!$D:$D),"—") | C11: =IFERROR(xlookup(A11,'FLEET REGISTER'!$B:$B,'FLEET REGISTER'!$E:$E),"—") | D11: =IFERROR(xlookup(A11,'FLEET REGISTER'!$B:$B,'FLEET REGISTER'!$F:$F),"—") | E11: =IFERROR(xlookup(A11,'FLEET REGISTER'!$B:$B,'FLEET REGISTER'!$G:$G),"—") | F11: =IFERROR(xlookup(A11,'FLEET REGISTER'!$B:$B,'FLEET REGISTER'!$H:$H),"—") | G11: =IFERROR(xlookup(A11,'RAW ODOMETER'!$A:$A,'RAW ODOMETER'!$M:$M,0),0) | H11: =IFERROR(xlookup(A11,'RAW FUEL DATA'!$A:$A,'RAW FUEL DATA'!$K:$K,0),0) | I11: =IFERROR(xlookup(A11,'RAW FUEL DATA'!$A:$A,'RAW FUEL DATA'!$L:$L,0),0) | J11: =IF(F11="Honda",40.5,12.6) | K11: =IF(I11=0,"No Data",IF(I11>=J11,"✔ Complied","✘ Not Complied")) | L11: =IFERROR(COUNTIFS('RAW TRIPS'!$A:$A,A11,'RAW TRIPS'!$G:$G,"Yes"),0) | M11: =IFERROR(COUNTIFS('RAW TRIPS'!$A:$A,A11,'RAW TRIPS'!$H:$H,"Yes"),0) | N11: =IFERROR(maxifs('RAW TRIPS'!$F:$F,'RAW TRIPS'!$A:$A,A11),0) | O11: =IF(N11=0,"No Data",IF(N11<=90,"✔ Complied","✘ SPEEDING")) | P11: =IF(N11>90,"⚑ SPEED VIOLATION","") | Q11: =IF(M11>0,"⚑ PAST MIDNIGHT",IF(L11>0,"⚑ PAST 10PM","")) | R11: =IF(K11="✘ Not Complied","⚑ FUEL NON-COMPLIANT","")
A12: KBB 108Q | B12: =IFERROR(xlookup(A12,'FLEET REGISTER'!$B:$B,'FLEET REGISTER'!$D:$D),"—") | C12: =IFERROR(xlookup(A12,'FLEET REGISTER'!$B:$B,'FLEET REGISTER'!$E:$E),"—") | D12: =IFERROR(xlookup(A12,'FLEET REGISTER'!$B:$B,'FLEET REGISTER'!$F:$F),"—") | E12: =IFERROR(xlookup(A12,'FLEET REGISTER'!$B:$B,'FLEET REGISTER'!$G:$G),"—") | F12: =IFERROR(xlookup(A12,'FLEET REGISTER'!$B:$B,'FLEET REGISTER'!$H:$H),"—") | G12: =IFERROR(xlookup(A12,'RAW ODOMETER'!$A:$A,'RAW ODOMETER'!$M:$M,0),0) | H12: =IFERROR(xlookup(A12,'RAW FUEL DATA'!$A:$A,'RAW FUEL DATA'!$K:$K,0),0) | I12: =IFERROR(xlookup(A12,'RAW FUEL DATA'!$A:$A,'RAW FUEL DATA'!$L:$L,0),0) | J12: =IF(F12="Honda",40.5,12.6) | K12: =IF(I12=0,"No Data",IF(I12>=J12,"✔ Complied","✘ Not Complied")) | L12: =IFERROR(COUNTIFS('RAW TRIPS'!$A:$A,A12,'RAW TRIPS'!$G:$G,"Yes"),0) | M12: =IFERROR(COUNTIFS('RAW TRIPS'!$A:$A,A12,'RAW TRIPS'!$H:$H,"Yes"),0) | N12: =IFERROR(maxifs('RAW TRIPS'!$F:$F,'RAW TRIPS'!$A:$A,A12),0) | O12: =IF(N12=0,"No Data",IF(N12<=90,"✔ Complied","✘ SPEEDING")) | P12: =IF(N12>90,"⚑ SPEED VIOLATION","") | Q12: =IF(M12>0,"⚑ PAST MIDNIGHT",IF(L12>0,"⚑ PAST 10PM","")) | R12: =IF(K12="✘ Not Complied","⚑ FUEL NON-COMPLIANT","")
A13: KBB 109Q | B13: =IFERROR(xlookup(A13,'FLEET REGISTER'!$B:$B,'FLEET REGISTER'!$D:$D),"—") | C13: =IFERROR(xlookup(A13,'FLEET REGISTER'!$B:$B,'FLEET REGISTER'!$E:$E),"—") | D13: =IFERROR(xlookup(A13,'FLEET REGISTER'!$B:$B,'FLEET REGISTER'!$F:$F),"—") | E13: =IFERROR(xlookup(A13,'FLEET REGISTER'!$B:$B,'FLEET REGISTER'!$G:$G),"—") | F13: =IFERROR(xlookup(A13,'FLEET REGISTER'!$B:$B,'FLEET REGISTER'!$H:$H),"—") | G13: =IFERROR(xlookup(A13,'RAW ODOMETER'!$A:$A,'RAW ODOMETER'!$M:$M,0),0) | H13: =IFERROR(xlookup(A13,'RAW FUEL DATA'!$A:$A,'RAW FUEL DATA'!$K:$K,0),0) | I13: =IFERROR(xlookup(A13,'RAW FUEL DATA'!$A:$A,'RAW FUEL DATA'!$L:$L,0),0) | J13: =IF(F13="Honda",40.5,12.6) | K13: =IF(I13=0,"No Data",IF(I13>=J13,"✔ Complied","✘ Not Complied")) | L13: =IFERROR(COUNTIFS('RAW TRIPS'!$A:$A,A13,'RAW TRIPS'!$G:$G,"Yes"),0) | M13: =IFERROR(COUNTIFS('RAW TRIPS'!$A:$A,A13,'RAW TRIPS'!$H:$H,"Yes"),0) | N13: =IFERROR(maxifs('RAW TRIPS'!$F:$F,'RAW TRIPS'!$A:$A,A13),0) | O13: =IF(N13=0,"No Data",IF(N13<=90,"✔ Complied","✘ SPEEDING")) | P13: =IF(N13>90,"⚑ SPEED VIOLATION","") | Q13: =IF(M13>0,"⚑ PAST MIDNIGHT",IF(L13>0,"⚑ PAST 10PM","")) | R13: =IF(K13="✘ Not Complied","⚑ FUEL NON-COMPLIANT","")
A14: KBB 110Q | B14: =IFERROR(xlookup(A14,'FLEET REGISTER'!$B:$B,'FLEET REGISTER'!$D:$D),"—") | C14: =IFERROR(xlookup(A14,'FLEET REGISTER'!$B:$B,'FLEET REGISTER'!$E:$E),"—") | D14: =IFERROR(xlookup(A14,'FLEET REGISTER'!$B:$B,'FLEET REGISTER'!$F:$F),"—") | E14: =IFERROR(xlookup(A14,'FLEET REGISTER'!$B:$B,'FLEET REGISTER'!$G:$G),"—") | F14: =IFERROR(xlookup(A14,'FLEET REGISTER'!$B:$B,'FLEET REGISTER'!$H:$H),"—") | G14: =IFERROR(xlookup(A14,'RAW ODOMETER'!$A:$A,'RAW ODOMETER'!$M:$M,0),0) | H14: =IFERROR(xlookup(A14,'RAW FUEL DATA'!$A:$A,'RAW FUEL DATA'!$K:$K,0),0) | I14: =IFERROR(xlookup(A14,'RAW FUEL DATA'!$A:$A,'RAW FUEL DATA'!$L:$L,0),0) | J14: =IF(F14="Honda",40.5,12.6) | K14: =IF(I14=0,"No Data",IF(I14>=J14,"✔ Complied","✘ Not Complied")) | L14: =IFERROR(COUNTIFS('RAW TRIPS'!$A:$A,A14,'RAW TRIPS'!$G:$G,"Yes"),0) | M14: =IFERROR(COUNTIFS('RAW TRIPS'!$A:$A,A14,'RAW TRIPS'!$H:$H,"Yes"),0) | N14: =IFERROR(maxifs('RAW TRIPS'!$F:$F,'RAW TRIPS'!$A:$A,A14),0) | O14: =IF(N14=0,"No Data",IF(N14<=90,"✔ Complied","✘ SPEEDING")) | P14: =IF(N14>90,"⚑ SPEED VIOLATION","") | Q14: =IF(M14>0,"⚑ PAST MIDNIGHT",IF(L14>0,"⚑ PAST 10PM","")) | R14: =IF(K14="✘ Not Complied","⚑ FUEL NON-COMPLIANT","")
A15: KBB 111Q | B15: =IFERROR(xlookup(A15,'FLEET REGISTER'!$B:$B,'FLEET REGISTER'!$D:$D),"—") | C15: =IFERROR(xlookup(A15,'FLEET REGISTER'!$B:$B,'FLEET REGISTER'!$E:$E),"—") | D15: =IFERROR(xlookup(A15,'FLEET REGISTER'!$B:$B,'FLEET REGISTER'!$F:$F),"—") | E15: =IFERROR(xlookup(A15,'FLEET REGISTER'!$B:$B,'FLEET REGISTER'!$G:$G),"—") | F15: =IFERROR(xlookup(A15,'FLEET REGISTER'!$B:$B,'FLEET REGISTER'!$H:$H),"—") | G15: =IFERROR(xlookup(A15,'RAW ODOMETER'!$A:$A,'RAW ODOMETER'!$M:$M,0),0) | H15: =IFERROR(xlookup(A15,'RAW FUEL DATA'!$A:$A,'RAW FUEL DATA'!$K:$K,0),0) | I15: =IFERROR(xlookup(A15,'RAW FUEL DATA'!$A:$A,'RAW FUEL DATA'!$L:$L,0),0) | J15: =IF(F15="Honda",40.5,12.6) | K15: =IF(I15=0,"No Data",IF(I15>=J15,"✔ Complied","✘ Not Complied")) | L15: =IFERROR(COUNTIFS('RAW TRIPS'!$A:$A,A15,'RAW TRIPS'!$G:$G,"Yes"),0) | M15: =IFERROR(COUNTIFS('RAW TRIPS'!$A:$A,A15,'RAW TRIPS'!$H:$H,"Yes"),0) | N15: =IFERROR(maxifs('RAW TRIPS'!$F:$F,'RAW TRIPS'!$A:$A,A15),0) | O15: =IF(N15=0,"No Data",IF(N15<=90,"✔ Complied","✘ SPEEDING")) | P15: =IF(N15>90,"⚑ SPEED VIOLATION","") | Q15: =IF(M15>0,"⚑ PAST MIDNIGHT",IF(L15>0,"⚑ PAST 10PM","")) | R15: =IF(K15="✘ Not Complied","⚑ FUEL NON-COMPLIANT","")
... A58: KAAC 315C | B58: =IFERROR(xlookup(A58,'FLEET REGISTER'!$B:$B,'FLEET REGISTER'!$D:$D),"—") | C58: =IFERROR(xlookup(A58,'FLEET REGISTER'!$B:$B,'FLEET REGISTER'!$E:$E),"—") | D58: =IFERROR(xlookup(A58,'FLEET REGISTER'!$B:$B,'FLEET REGISTER'!$F:$F),"—") | E58: =IFERROR(xlookup(A58,'FLEET REGISTER'!$B:$B,'FLEET REGISTER'!$G:$G),"—") | F58: =IFERROR(xlookup(A58,'FLEET REGISTER'!$B:$B,'FLEET REGISTER'!$H:$H),"—") | G58: =IFERROR(xlookup(A58,'RAW ODOMETER'!$A:$A,'RAW ODOMETER'!$M:$M,0),0) | H58: =IFERROR(xlookup(A58,'RAW FUEL DATA'!$A:$A,'RAW FUEL DATA'!$K:$K,0),0) | I58: =IFERROR(xlookup(A58,'RAW FUEL DATA'!$A:$A,'RAW FUEL DATA'!$L:$L,0),0) | J58: =IF(F58="Honda",40.5,12.6) | K58: =IF(I58=0,"No Data",IF(I58>=J58,"✔ Complied","✘ Not Complied")) | L58: =IFERROR(COUNTIFS('RAW TRIPS'!$A:$A,A58,'RAW TRIPS'!$G:$G,"Yes"),0) | M58: =IFERROR(COUNTIFS('RAW TRIPS'!$A:$A,A58,'RAW TRIPS'!$H:$H,"Yes"),0) | N58: =IFERROR(maxifs('RAW TRIPS'!$F:$F,'RAW TRIPS'!$A:$A,A58),0) | O58: =IF(N58=0,"No Data",IF(N58<=90,"✔ Complied","✘ SPEEDING")) | P58: =IF(N58>90,"⚑ SPEED VIOLATION","") | Q58: =IF(M58>0,"⚑ PAST MIDNIGHT",IF(L58>0,"⚑ PAST 10PM","")) | R58: =IF(K58="✘ Not Complied","⚑ FUEL NON-COMPLIANT","")

Sheet SPEED FLAGS
A1: 🚨 SPEED FLAGS — ALL TRIPS EXCEEDING 90 km/h | Speed Limit: 90 km/h
A2: Columns A–F auto-populate via FILTER from RAW TRIPS. Columns G–L require manual entry. Green rows = permission granted. Red rows = pending action.
A3: Car Reg | B3: Departure Time | C3: End Time | D3: Top Speed (km/h) | E3: Driver Name | F3: Region | G3: Permission? | H3: Reason for Permission | I3: Discipline Action | J3: Action Date | K3: Issued By | L3: Remarks
A4: =IFERROR(filter('RAW TRIPS'!A4:A5000,'RAW TRIPS'!F4:F5000>90),"") | B4: =IFERROR(filter('RAW TRIPS'!B4:B5000,'RAW TRIPS'!F4:F5000>90),"") | C4: =IFERROR(filter('RAW TRIPS'!C4:C5000,'RAW TRIPS'!F4:F5000>90),"") | D4: =IFERROR(filter('RAW TRIPS'!F4:F5000,'RAW TRIPS'!F4:F5000>90),"") | E4: =IF(A4="","",IFERROR(xlookup(A4,'FLEET REGISTER'!$B:$B,'FLEET REGISTER'!$D:$D),"Unknown")) | F4: =IF(A4="","",IFERROR(xlookup(A4,'FLEET REGISTER'!$B:$B,'FLEET REGISTER'!$F:$F),"Unknown"))
E5: =IF(A5="","",IFERROR(xlookup(A5,'FLEET REGISTER'!$B:$B,'FLEET REGISTER'!$D:$D),"Unknown")) | F5: =IF(A5="","",IFERROR(xlookup(A5,'FLEET REGISTER'!$B:$B,'FLEET REGISTER'!$F:$F),"Unknown"))
E6: =IF(A6="","",IFERROR(xlookup(A6,'FLEET REGISTER'!$B:$B,'FLEET REGISTER'!$D:$D),"Unknown")) | F6: =IF(A6="","",IFERROR(xlookup(A6,'FLEET REGISTER'!$B:$B,'FLEET REGISTER'!$F:$F),"Unknown"))
E7: =IF(A7="","",IFERROR(xlookup(A7,'FLEET REGISTER'!$B:$B,'FLEET REGISTER'!$D:$D),"Unknown")) | F7: =IF(A7="","",IFERROR(xlookup(A7,'FLEET REGISTER'!$B:$B,'FLEET REGISTER'!$F:$F),"Unknown"))
E8: =IF(A8="","",IFERROR(xlookup(A8,'FLEET REGISTER'!$B:$B,'FLEET REGISTER'!$D:$D),"Unknown")) | F8: =IF(A8="","",IFERROR(xlookup(A8,'FLEET REGISTER'!$B:$B,'FLEET REGISTER'!$F:$F),"Unknown"))
E9: =IF(A9="","",IFERROR(xlookup(A9,'FLEET REGISTER'!$B:$B,'FLEET REGISTER'!$D:$D),"Unknown")) | F9: =IF(A9="","",IFERROR(xlookup(A9,'FLEET REGISTER'!$B:$B,'FLEET REGISTER'!$F:$F),"Unknown"))
E10: =IF(A10="","",IFERROR(xlookup(A10,'FLEET REGISTER'!$B:$B,'FLEET REGISTER'!$D:$D),"Unknown")) | F10: =IF(A10="","",IFERROR(xlookup(A10,'FLEET REGISTER'!$B:$B,'FLEET REGISTER'!$F:$F),"Unknown"))
E11: =IF(A11="","",IFERROR(xlookup(A11,'FLEET REGISTER'!$B:$B,'FLEET REGISTER'!$D:$D),"Unknown")) | F11: =IF(A11="","",IFERROR(xlookup(A11,'FLEET REGISTER'!$B:$B,'FLEET REGISTER'!$F:$F),"Unknown"))
E12: =IF(A12="","",IFERROR(xlookup(A12,'FLEET REGISTER'!$B:$B,'FLEET REGISTER'!$D:$D),"Unknown")) | F12: =IF(A12="","",IFERROR(xlookup(A12,'FLEET REGISTER'!$B:$B,'FLEET REGISTER'!$F:$F),"Unknown"))
E13: =IF(A13="","",IFERROR(xlookup(A13,'FLEET REGISTER'!$B:$B,'FLEET REGISTER'!$D:$D),"Unknown")) | F13: =IF(A13="","",IFERROR(xlookup(A13,'FLEET REGISTER'!$B:$B,'FLEET REGISTER'!$F:$F),"Unknown"))
E14: =IF(A14="","",IFERROR(xlookup(A14,'FLEET REGISTER'!$B:$B,'FLEET REGISTER'!$D:$D),"Unknown")) | F14: =IF(A14="","",IFERROR(xlookup(A14,'FLEET REGISTER'!$B:$B,'FLEET REGISTER'!$F:$F),"Unknown"))
E15: =IF(A15="","",IFERROR(xlookup(A15,'FLEET REGISTER'!$B:$B,'FLEET REGISTER'!$D:$D),"Unknown")) | F15: =IF(A15="","",IFERROR(xlookup(A15,'FLEET REGISTER'!$B:$B,'FLEET REGISTER'!$F:$F),"Unknown"))
E16: =IF(A16="","",IFERROR(xlookup(A16,'FLEET REGISTER'!$B:$B,'FLEET REGISTER'!$D:$D),"Unknown")) | F16: =IF(A16="","",IFERROR(xlookup(A16,'FLEET REGISTER'!$B:$B,'FLEET REGISTER'!$F:$F),"Unknown"))
... E499: =IF(A499="","",IFERROR(xlookup(A499,'FLEET REGISTER'!$B:$B,'FLEET REGISTER'!$D:$D),"Unknown")) | F499: =IF(A499="","",IFERROR(xlookup(A499,'FLEET REGISTER'!$B:$B,'FLEET REGISTER'!$F:$F),"Unknown"))

Sheet LATE HOURS FLAGS
A1: 🌙 LATE HOURS FLAGS — DRIVING PAST 10PM & PAST MIDNIGHT
A2: Columns A–F auto-populate via FILTER. Amber = past 10pm only. Red = past midnight. Columns G–L require manual entry. Use "Permission Granted" to deprioritize rows.
A3: Car Reg | B3: End Time | C3: Past 10pm (Days) | D3: Past Midnight (Days) | E3: Severity | F3: Region | G3: Permission? | H3: Reason for Permission | I3: Discipline Action | J3: Action Date | K3: Issued By | L3: Remarks
A4: =IFERROR(filter('MONTHLY ANALYSIS'!$A$4:$A$58,('MONTHLY ANALYSIS'!$L$4:$L$58>0)+('MONTHLY ANALYSIS'!$M$4:$M$58>0)),"") | B4: =IF(A4="","",IFERROR(xlookup(A4,'MONTHLY ANALYSIS'!$A:$A,'MONTHLY ANALYSIS'!$L:$L),0)) | C4: =IF(A4="","",IFERROR(xlookup(A4,'MONTHLY ANALYSIS'!$A:$A,'MONTHLY ANALYSIS'!$L:$L),0)) | D4: =IF(A4="","",IFERROR(xlookup(A4,'MONTHLY ANALYSIS'!$A:$A,'MONTHLY ANALYSIS'!$M:$M),0)) | E4: =IF(A4="","",IF(D4>0,"⚑ PAST MIDNIGHT","⚠ PAST 10PM ONLY")) | F4: =IF(A4="","",IFERROR(xlookup(A4,'FLEET REGISTER'!$B:$B,'FLEET REGISTER'!$F:$F),"Unknown"))
A5: =IF(A4="","","") | B5: =IF(A5="","",IFERROR(xlookup(A5,'MONTHLY ANALYSIS'!$A:$A,'MONTHLY ANALYSIS'!$L:$L),0)) | C5: =IF(A5="","",IFERROR(xlookup(A5,'MONTHLY ANALYSIS'!$A:$A,'MONTHLY ANALYSIS'!$L:$L),0)) | D5: =IF(A5="","",IFERROR(xlookup(A5,'MONTHLY ANALYSIS'!$A:$A,'MONTHLY ANALYSIS'!$M:$M),0)) | E5: =IF(A5="","",IF(D5>0,"⚑ PAST MIDNIGHT","⚠ PAST 10PM ONLY")) | F5: =IF(A5="","",IFERROR(xlookup(A5,'FLEET REGISTER'!$B:$B,'FLEET REGISTER'!$F:$F),"Unknown"))
A6: =IF(A5="","","") | B6: =IF(A6="","",IFERROR(xlookup(A6,'MONTHLY ANALYSIS'!$A:$A,'MONTHLY ANALYSIS'!$L:$L),0)) | C6: =IF(A6="","",IFERROR(xlookup(A6,'MONTHLY ANALYSIS'!$A:$A,'MONTHLY ANALYSIS'!$L:$L),0)) | D6: =IF(A6="","",IFERROR(xlookup(A6,'MONTHLY ANALYSIS'!$A:$A,'MONTHLY ANALYSIS'!$M:$M),0)) | E6: =IF(A6="","",IF(D6>0,"⚑ PAST MIDNIGHT","⚠ PAST 10PM ONLY")) | F6: =IF(A6="","",IFERROR(xlookup(A6,'FLEET REGISTER'!$B:$B,'FLEET REGISTER'!$F:$F),"Unknown"))
A7: =IF(A6="","","") | B7: =IF(A7="","",IFERROR(xlookup(A7,'MONTHLY ANALYSIS'!$A:$A,'MONTHLY ANALYSIS'!$L:$L),0)) | C7: =IF(A7="","",IFERROR(xlookup(A7,'MONTHLY ANALYSIS'!$A:$A,'MONTHLY ANALYSIS'!$L:$L),0)) | D7: =IF(A7="","",IFERROR(xlookup(A7,'MONTHLY ANALYSIS'!$A:$A,'MONTHLY ANALYSIS'!$M:$M),0)) | E7: =IF(A7="","",IF(D7>0,"⚑ PAST MIDNIGHT","⚠ PAST 10PM ONLY")) | F7: =IF(A7="","",IFERROR(xlookup(A7,'FLEET REGISTER'!$B:$B,'FLEET REGISTER'!$F:$F),"Unknown"))
A8: =IF(A7="","","") | B8: =IF(A8="","",IFERROR(xlookup(A8,'MONTHLY ANALYSIS'!$A:$A,'MONTHLY ANALYSIS'!$L:$L),0)) | C8: =IF(A8="","",IFERROR(xlookup(A8,'MONTHLY ANALYSIS'!$A:$A,'MONTHLY ANALYSIS'!$L:$L),0)) | D8: =IF(A8="","",IFERROR(xlookup(A8,'MONTHLY ANALYSIS'!$A:$A,'MONTHLY ANALYSIS'!$M:$M),0)) | E8: =IF(A8="","",IF(D8>0,"⚑ PAST MIDNIGHT","⚠ PAST 10PM ONLY")) | F8: =IF(A8="","",IFERROR(xlookup(A8,'FLEET REGISTER'!$B:$B,'FLEET REGISTER'!$F:$F),"Unknown"))
A9: =IF(A8="","","") | B9: =IF(A9="","",IFERROR(xlookup(A9,'MONTHLY ANALYSIS'!$A:$A,'MONTHLY ANALYSIS'!$L:$L),0)) | C9: =IF(A9="","",IFERROR(xlookup(A9,'MONTHLY ANALYSIS'!$A:$A,'MONTHLY ANALYSIS'!$L:$L),0)) | D9: =IF(A9="","",IFERROR(xlookup(A9,'MONTHLY ANALYSIS'!$A:$A,'MONTHLY ANALYSIS'!$M:$M),0)) | E9: =IF(A9="","",IF(D9>0,"⚑ PAST MIDNIGHT","⚠ PAST 10PM ONLY")) | F9: =IF(A9="","",IFERROR(xlookup(A9,'FLEET REGISTER'!$B:$B,'FLEET REGISTER'!$F:$F),"Unknown"))
A10: =IF(A9="","","") | B10: =IF(A10="","",IFERROR(xlookup(A10,'MONTHLY ANALYSIS'!$A:$A,'MONTHLY ANALYSIS'!$L:$L),0)) | C10: =IF(A10="","",IFERROR(xlookup(A10,'MONTHLY ANALYSIS'!$A:$A,'MONTHLY ANALYSIS'!$L:$L),0)) | D10: =IF(A10="","",IFERROR(xlookup(A10,'MONTHLY ANALYSIS'!$A:$A,'MONTHLY ANALYSIS'!$M:$M),0)) | E10: =IF(A10="","",IF(D10>0,"⚑ PAST MIDNIGHT","⚠ PAST 10PM ONLY")) | F10: =IF(A10="","",IFERROR(xlookup(A10,'FLEET REGISTER'!$B:$B,'FLEET REGISTER'!$F:$F),"Unknown"))
A11: =IF(A10="","","") | B11: =IF(A11="","",IFERROR(xlookup(A11,'MONTHLY ANALYSIS'!$A:$A,'MONTHLY ANALYSIS'!$L:$L),0)) | C11: =IF(A11="","",IFERROR(xlookup(A11,'MONTHLY ANALYSIS'!$A:$A,'MONTHLY ANALYSIS'!$L:$L),0)) | D11: =IF(A11="","",IFERROR(xlookup(A11,'MONTHLY ANALYSIS'!$A:$A,'MONTHLY ANALYSIS'!$M:$M),0)) | E11: =IF(A11="","",IF(D11>0,"⚑ PAST MIDNIGHT","⚠ PAST 10PM ONLY")) | F11: =IF(A11="","",IFERROR(xlookup(A11,'FLEET REGISTER'!$B:$B,'FLEET REGISTER'!$F:$F),"Unknown"))
A12: =IF(A11="","","") | B12: =IF(A12="","",IFERROR(xlookup(A12,'MONTHLY ANALYSIS'!$A:$A,'MONTHLY ANALYSIS'!$L:$L),0)) | C12: =IF(A12="","",IFERROR(xlookup(A12,'MONTHLY ANALYSIS'!$A:$A,'MONTHLY ANALYSIS'!$L:$L),0)) | D12: =IF(A12="","",IFERROR(xlookup(A12,'MONTHLY ANALYSIS'!$A:$A,'MONTHLY ANALYSIS'!$M:$M),0)) | E12: =IF(A12="","",IF(D12>0,"⚑ PAST MIDNIGHT","⚠ PAST 10PM ONLY")) | F12: =IF(A12="","",IFERROR(xlookup(A12,'FLEET REGISTER'!$B:$B,'FLEET REGISTER'!$F:$F),"Unknown"))
